#VRML_SIM R2025a utf8

WorldInfo {
  title "Simplified Robot Soccer - 1v1"
  basicTimeStep 64
  contactProperties [
    ContactProperties {
      material1 "ball"
      coulombFriction [
        0.5
      ]
      bounce 0
      bounceVelocity 0.001
      softCFM 0.0001
    }
    ContactProperties {
      material1 "ball"
      material2 "robot"
      coulombFriction [
        0.2
      ]
      bounce 0
      bounceVelocity 0.001
    }
  ]
}
Viewpoint {
  fieldOfView 1
  orientation -0.770006289556767 0.4511597967392669 -0.4511597852748004 1.8292272942934478
  position -4.2760815455027394 7.098020215531489 0.4301169504560383
}
Background {
  skyColor [
    0.15 0.15 0.18
  ]
}
DirectionalLight {
  direction 0 -1 0
  intensity 0.8
}
DirectionalLight {
  direction -0.4 -0.7 -0.6
  intensity 0.5
}
DirectionalLight {
  direction 0.4 -0.7 0.6
  intensity 0.4
}
DirectionalLight {
  direction 0 -0.5 -1
  intensity 0.3
}
DEF FIELD_FLOOR Solid {
  translation 0 -0.02 0
  children [
    Shape {
      appearance PBRAppearance {
        baseColor 0.13 0.55 0.13
        roughness 0.95
        metalness 0
      }
      geometry Box {
        size 4.2 0.04 3.2
      }
    }
  ]
  name "field_floor"
  contactMaterial "floor"
  boundingObject Box {
    size 4.2 0.04 3.2
  }
  locked TRUE
}
DEF LINE_TOP Solid {
  translation 0 0.001 1
  children [
    Shape {
      appearance DEF LINE_APP PBRAppearance {
        roughness 0.5
        metalness 0
      }
      geometry Box {
        size 3.04 0.002 0.022
      }
    }
  ]
  name "line_top"
  locked TRUE
}
DEF LINE_BOT Solid {
  translation 0 0.001 -1
  children [
    Shape {
      appearance USE LINE_APP
      geometry Box {
        size 3.04 0.002 0.022
      }
    }
  ]
  name "line_bot"
  locked TRUE
}
DEF LINE_LEFT Solid {
  translation -1.5 0.001 0
  children [
    Shape {
      appearance USE LINE_APP
      geometry Box {
        size 0.022 0.002 2.044
      }
    }
  ]
  name "line_left"
  locked TRUE
}
DEF LINE_RIGHT Solid {
  translation 1.5 0.001 0
  children [
    Shape {
      appearance USE LINE_APP
      geometry Box {
        size 0.022 0.002 2.044
      }
    }
  ]
  name "line_right"
  locked TRUE
}
DEF LINE_CTR Solid {
  translation 0 0.001 0
  children [
    Shape {
      appearance USE LINE_APP
      geometry Box {
        size 0.022 0.002 2
      }
    }
  ]
  name "line_ctr"
  locked TRUE
}
DEF CENTRE_CIRCLE Solid {
  translation 0 0.002 0
  children [
    Shape {
      appearance USE LINE_APP
      geometry IndexedFaceSet {
        coord Coordinate {
          point [
            0.339 0 0, 0.3325 0 0.0661, 0.3132 0 0.1297, 0.2819 0 0.1883, 0.2397 0 0.2397, 0.1883 0 0.2819, 0.1297 0 0.3132, 0.0661 0 0.3325, 0 0 0.339, -0.0661 0 0.3325, -0.1297 0 0.3132, -0.1883 0 0.2819, -0.2397 0 0.2397, -0.2819 0 0.1883, -0.3132 0 0.1297, -0.3325 0 0.0661, -0.339 0 0, -0.3325 0 -0.0661, -0.3132 0 -0.1297, -0.2819 0 -0.1883, -0.2397 0 -0.2397, -0.1883 0 -0.2819, -0.1297 0 -0.3132, -0.0661 0 -0.3325, 0 0 -0.339, 0.0661 0 -0.3325, 0.1297 0 -0.3132, 0.1883 0 -0.2819, 0.2397 0 -0.2397, 0.2819 0 -0.1883, 0.3132 0 -0.1297, 0.3325 0 -0.0661, 0.361 0 0, 0.3541 0 0.0704, 0.3335 0 0.1382, 0.3002 0 0.2006, 0.2553 0 0.2553, 0.2006 0 0.3002, 0.1382 0 0.3335, 0.0704 0 0.3541, 0 0 0.361, -0.0704 0 0.3541, -0.1382 0 0.3335, -0.2006 0 0.3002, -0.2553 0 0.2553, -0.3002 0 0.2006, -0.3335 0 0.1382, -0.3541 0 0.0704, -0.361 0 0, -0.3541 0 -0.0704, -0.3335 0 -0.1382, -0.3002 0 -0.2006, -0.2553 0 -0.2553, -0.2006 0 -0.3002, -0.1382 0 -0.3335, -0.0704 0 -0.3541, 0 0 -0.361, 0.0704 0 -0.3541, 0.1382 0 -0.3335, 0.2006 0 -0.3002, 0.2553 0 -0.2553, 0.3002 0 -0.2006, 0.3335 0 -0.1382, 0.3541 0 -0.0704
          ]
        }
        coordIndex [
          0, 1, 33, 32, -1, 1, 2, 34, 33, -1, 2, 3, 35, 34, -1, 3, 4, 36, 35, -1, 4, 5, 37, 36, -1, 5, 6, 38, 37, -1, 6, 7, 39, 38, -1, 7, 8, 40, 39, -1, 8, 9, 41, 40, -1, 9, 10, 42, 41, -1, 10, 11, 43, 42, -1, 11, 12, 44, 43, -1, 12, 13, 45, 44, -1, 13, 14, 46, 45, -1, 14, 15, 47, 46, -1, 15, 16, 48, 47, -1, 16, 17, 49, 48, -1, 17, 18, 50, 49, -1, 18, 19, 51, 50, -1, 19, 20, 52, 51, -1, 20, 21, 53, 52, -1, 21, 22, 54, 53, -1, 22, 23, 55, 54, -1, 23, 24, 56, 55, -1, 24, 25, 57, 56, -1, 25, 26, 58, 57, -1, 26, 27, 59, 58, -1, 27, 28, 60, 59, -1, 28, 29, 61, 60, -1, 29, 30, 62, 61, -1, 30, 31, 63, 62, -1, 31, 0, 32, 63, -1
        ]
      }
    }
  ]
  name "centre_circle"
  locked TRUE
}
DEF CTR_SPOT Solid {
  translation 0 0.002 0
  children [
    Shape {
      appearance USE LINE_APP
      geometry Cylinder {
        height 0.003
        radius 0.035
      }
    }
  ]
  name "ctr_spot"
  locked TRUE
}
DEF GA_L_TOP Solid {
  translation -1.3 0.001 0.5
  children [
    Shape {
      appearance USE LINE_APP
      geometry Box {
        size 0.4 0.002 0.022
      }
    }
  ]
  name "ga_l_top"
  locked TRUE
}
DEF GA_L_BOT Solid {
  translation -1.3 0.001 -0.5
  children [
    Shape {
      appearance USE LINE_APP
      geometry Box {
        size 0.4 0.002 0.022
      }
    }
  ]
  name "ga_l_bot"
  locked TRUE
}
DEF GA_L_SIDE Solid {
  translation -1.1 0.001 0
  children [
    Shape {
      appearance USE LINE_APP
      geometry Box {
        size 0.022 0.002 1
      }
    }
  ]
  name "ga_l_side"
  locked TRUE
}
DEF GA_R_TOP Solid {
  translation 1.3 0.001 0.5
  children [
    Shape {
      appearance USE LINE_APP
      geometry Box {
        size 0.4 0.002 0.022
      }
    }
  ]
  name "ga_r_top"
  locked TRUE
}
DEF GA_R_BOT Solid {
  translation 1.3 0.001 -0.5
  children [
    Shape {
      appearance USE LINE_APP
      geometry Box {
        size 0.4 0.002 0.022
      }
    }
  ]
  name "ga_r_bot"
  locked TRUE
}
DEF GA_R_SIDE Solid {
  translation 1.1 0.001 0
  children [
    Shape {
      appearance USE LINE_APP
      geometry Box {
        size 0.022 0.002 1
      }
    }
  ]
  name "ga_r_side"
  locked TRUE
}
DEF GOAL_L_BACK Solid {
  translation -1.75 0.2 0
  children [
    Shape {
      appearance DEF GOAL_APP PBRAppearance {
        roughness 0.3
        metalness 0.15
      }
      geometry Box {
        size 0.05 0.4 0.7
      }
    }
  ]
  name "goal_l_back"
  boundingObject Box {
    size 0.05 0.4 0.7
  }
  locked TRUE
}
DEF GOAL_L_POST_P Solid {
  translation -1.625 0.2 0.35
  children [
    Shape {
      appearance USE GOAL_APP
      geometry Box {
        size 0.25 0.4 0.05
      }
    }
  ]
  name "goal_l_post_p"
  boundingObject Box {
    size 0.25 0.4 0.05
  }
  locked TRUE
}
DEF GOAL_L_POST_N Solid {
  translation -1.625 0.2 -0.35
  children [
    Shape {
      appearance USE GOAL_APP
      geometry Box {
        size 0.25 0.4 0.05
      }
    }
  ]
  name "goal_l_post_n"
  boundingObject Box {
    size 0.25 0.4 0.05
  }
  locked TRUE
}
DEF GOAL_L_CROSS Solid {
  translation -1.625 0.41 0
  children [
    Shape {
      appearance USE GOAL_APP
      geometry Box {
        size 0.25 0.022 0.75
      }
    }
  ]
  name "goal_l_cross"
  boundingObject Box {
    size 0.25 0.022 0.75
  }
  locked TRUE
}
DEF GOAL_R_BACK Solid {
  translation 1.75 0.2 0
  children [
    Shape {
      appearance USE GOAL_APP
      geometry Box {
        size 0.05 0.4 0.7
      }
    }
  ]
  name "goal_r_back"
  boundingObject Box {
    size 0.05 0.4 0.7
  }
  locked TRUE
}
DEF GOAL_R_POST_P Solid {
  translation 1.625 0.2 0.35
  children [
    Shape {
      appearance USE GOAL_APP
      geometry Box {
        size 0.25 0.4 0.05
      }
    }
  ]
  name "goal_r_post_p"
  boundingObject Box {
    size 0.25 0.4 0.05
  }
  locked TRUE
}
DEF GOAL_R_POST_N Solid {
  translation 1.625 0.2 -0.35
  children [
    Shape {
      appearance USE GOAL_APP
      geometry Box {
        size 0.25 0.4 0.05
      }
    }
  ]
  name "goal_r_post_n"
  boundingObject Box {
    size 0.25 0.4 0.05
  }
  locked TRUE
}
DEF GOAL_R_CROSS Solid {
  translation 1.625 0.41 0
  children [
    Shape {
      appearance USE GOAL_APP
      geometry Box {
        size 0.25 0.022 0.75
      }
    }
  ]
  name "goal_r_cross"
  boundingObject Box {
    size 0.25 0.022 0.75
  }
  locked TRUE
}
DEF WALL_NEAR Solid {
  translation 0 0.175 1.05
  children [
    Shape {
      appearance DEF WALL_APP PBRAppearance {
        baseColor 0.28 0.28 0.28
        roughness 0.85
        metalness 0.05
      }
      geometry Box {
        size 3.28 0.35 0.1
      }
    }
  ]
  name "wall_near"
  boundingObject Box {
    size 3.28 0.35 0.1
  }
  locked TRUE
}
DEF WALL_FAR Solid {
  translation 0 0.175 -1.05
  children [
    Shape {
      appearance USE WALL_APP
      geometry Box {
        size 3.28 0.35 0.1
      }
    }
  ]
  name "wall_far"
  boundingObject Box {
    size 3.28 0.35 0.1
  }
  locked TRUE
}
DEF ENDW_L_TOP Solid {
  translation -1.54 0.175 0.695
  children [
    Shape {
      appearance USE WALL_APP
      geometry Box {
        size 0.08 0.35 0.61
      }
    }
  ]
  name "endw_l_top"
  boundingObject Box {
    size 0.08 0.35 0.61
  }
  locked TRUE
}
DEF ENDW_L_BOT Solid {
  translation -1.54 0.175 -0.695
  children [
    Shape {
      appearance USE WALL_APP
      geometry Box {
        size 0.08 0.35 0.61
      }
    }
  ]
  name "endw_l_bot"
  boundingObject Box {
    size 0.08 0.35 0.61
  }
  locked TRUE
}
DEF ENDW_R_TOP Solid {
  translation 1.54 0.175 0.695
  children [
    Shape {
      appearance USE WALL_APP
      geometry Box {
        size 0.08 0.35 0.61
      }
    }
  ]
  name "endw_r_top"
  boundingObject Box {
    size 0.08 0.35 0.61
  }
  locked TRUE
}
DEF ENDW_R_BOT Solid {
  translation 1.54 0.175 -0.695
  children [
    Shape {
      appearance USE WALL_APP
      geometry Box {
        size 0.08 0.35 0.61
      }
    }
  ]
  name "endw_r_bot"
  boundingObject Box {
    size 0.08 0.35 0.61
  }
  locked TRUE
}
DEF BALL Solid {
  translation 0 0.043 0
  children [
    Shape {
      appearance PBRAppearance {
        baseColor 0.96 0.44 0.04
        roughness 0.6
        metalness 0
        emissiveColor 0.15 0.06 0
      }
      geometry Sphere {
        radius 0.043
        subdivision 3
      }
    }
  ]
  name "ball"
  contactMaterial "ball"
  boundingObject Sphere {
    radius 0.043
  }
  physics Physics {
    density -1
    mass 0.04
  }
}
DEF ROBOT_BLUE Robot {
  translation -0.75 0.032 0
  rotation 0 1 0 0
  children [
    Pose {
      rotation 1 0 0 1.5707963
      children [
        Shape {
          appearance PBRAppearance {
            baseColor 0.04 0.14 0.72
            roughness 0.72
            metalness 0.08
          }
          geometry Cylinder {
            height 0.06
            radius 0.09
          }
        }
      ]
    }
    Pose {
      rotation 1 0 0 1.5707963
      translation 0 -0.026 0
      children [
        Shape {
          appearance PBRAppearance {
            baseColor 0.08 0.08 0.12
            roughness 0.88
            metalness 0
          }
          geometry Cylinder {
            height 0.008
            radius 0.093
          }
        }
      ]
    }
    Pose {
      rotation 1 0 0 1.5707963
      translation 0 -0.003 0
      children [
        Shape {
          appearance PBRAppearance {
            baseColor 0.25 0.45 1
            roughness 0.3
            metalness 0
            emissiveColor 0.1 0.22 0.85
          }
          geometry Cylinder {
            height 0.004
            radius 0.091
          }
        }
      ]
    }
    Pose {
      translation 0 0.034 0
      children [
        Shape {
          appearance PBRAppearance {
            roughness 0.2
            metalness 0
            emissiveColor 0.72 0.72 0.72
          }
          geometry IndexedFaceSet {
            coord Coordinate {
              point [
                0.062 0 0
                -0.021 0 0.04
                -0.021 0 -0.04
              ]
            }
            coordIndex [
              0, 1, 2, -1, 2, 1, 0, -1
            ]
          }
        }
      ]
    }
    Pose {
      translation 0.03 0.034 0.03
      children [
        Shape {
          appearance PBRAppearance {
            baseColor 0.25 0.45 1
            roughness 0.2
            metalness 0
            emissiveColor 0.1 0.22 0.85
          }
          geometry Cylinder {
            height 0.005
            radius 0.007
          }
        }
      ]
    }
    Pose {
      translation 0.03 0.034 -0.03
      children [
        Shape {
          appearance PBRAppearance {
            baseColor 0.25 0.45 1
            roughness 0.2
            metalness 0
            emissiveColor 0.1 0.22 0.85
          }
          geometry Cylinder {
            height 0.005
            radius 0.007
          }
        }
      ]
    }
    Pose {
      translation -0.03 0.034 0.03
      children [
        Shape {
          appearance PBRAppearance {
            baseColor 0.25 0.45 1
            roughness 0.2
            metalness 0
            emissiveColor 0.1 0.22 0.85
          }
          geometry Cylinder {
            height 0.005
            radius 0.007
          }
        }
      ]
    }
    Pose {
      translation -0.03 0.034 -0.03
      children [
        Shape {
          appearance PBRAppearance {
            baseColor 0.25 0.45 1
            roughness 0.2
            metalness 0
            emissiveColor 0.1 0.22 0.85
          }
          geometry Cylinder {
            height 0.005
            radius 0.007
          }
        }
      ]
    }
    # BLUE wheel1: eixo radial para fora; centro = 0.09 + 0.011 = 0.101
    HingeJoint {
      jointParameters HingeJointParameters {
        axis 1.0000 0 0.0000
        anchor 0.10100 0 0.00000
      }
      device [
        RotationalMotor {
          name "wheel1 motor"
          maxVelocity 5
        }
      ]
      endPoint Solid {
        translation 0.10100 0 0.00000
        rotation 0 0 1 0
        children [
          Pose {
            rotation 0.0000 0 -1.0000 1.5707963
            children [
              Shape {
                appearance PBRAppearance {
                  baseColor 0.08 0.08 0.10
                  roughness 0.93
                  metalness 0
                }
                geometry Cylinder {
                  height 0.022
                  radius 0.032
                }
              }
            ]
          }
          Pose {
            rotation 0.0000 0 -1.0000 1.5707963
            children [
              Shape {
                appearance PBRAppearance {
                  baseColor 0.72 0.72 0.74
                  roughness 0.42
                  metalness 0.32
                }
                geometry Cylinder {
                  height 0.024
                  radius 0.015
                }
              }
            ]
          }
        ]
        name "titan_wheel1"
        contactMaterial "robot"
        boundingObject Sphere {
          radius 0.032
        }
        physics Physics {
          density -1
          mass 0.1
        }
      }
    }
    # BLUE wheel2: eixo radial para fora; centro = 0.101 em 120 graus
    HingeJoint {
      jointParameters HingeJointParameters {
        axis 1.0000 0 0.0000
        anchor -0.05050 0 0.08747
      }
      device [
        RotationalMotor {
          name "wheel2 motor"
          maxVelocity 5
        }
      ]
      endPoint Solid {
        translation -0.05050 0 0.08747
        rotation 0 0 1 0
        children [
          Pose {
            rotation 0.0000 0 -1.0000 1.5707963
            children [
              Shape {
                appearance PBRAppearance {
                  baseColor 0.08 0.08 0.10
                  roughness 0.93
                  metalness 0
                }
                geometry Cylinder {
                  height 0.022
                  radius 0.032
                }
              }
            ]
          }
          Pose {
            rotation 0.0000 0 -1.0000 1.5707963
            children [
              Shape {
                appearance PBRAppearance {
                  baseColor 0.72 0.72 0.74
                  roughness 0.42
                  metalness 0.32
                }
                geometry Cylinder {
                  height 0.024
                  radius 0.015
                }
              }
            ]
          }
        ]
        name "titan_wheel2"
        contactMaterial "robot"
        boundingObject Sphere {
          radius 0.032
        }
        physics Physics {
          density -1
          mass 0.1
        }
      }
    }
    # BLUE wheel3: eixo radial para fora; centro = 0.101 em 240 graus
    HingeJoint {
      jointParameters HingeJointParameters {
        axis 1.0000 0 0.0000
        anchor -0.05050 0 -0.08747
      }
      device [
        RotationalMotor {
          name "wheel3 motor"
          maxVelocity 5
        }
      ]
      endPoint Solid {
        translation -0.05050 0 -0.08747
        rotation 0 0 1 0
        children [
          Pose {
            rotation 0.0000 0 -1.0000 1.5707963
            children [
              Shape {
                appearance PBRAppearance {
                  baseColor 0.08 0.08 0.10
                  roughness 0.93
                  metalness 0
                }
                geometry Cylinder {
                  height 0.022
                  radius 0.032
                }
              }
            ]
          }
          Pose {
            rotation 0.0000 0 -1.0000 1.5707963
            children [
              Shape {
                appearance PBRAppearance {
                  baseColor 0.72 0.72 0.74
                  roughness 0.42
                  metalness 0.32
                }
                geometry Cylinder {
                  height 0.024
                  radius 0.015
                }
              }
            ]
          }
        ]
        name "titan_wheel3"
        contactMaterial "robot"
        boundingObject Sphere {
          radius 0.032
        }
        physics Physics {
          density -1
          mass 0.1
        }
      }
    }
    Receiver {
      channel -1
    }
  ]
  name "robot_blue"
  contactMaterial "robot"
  boundingObject Pose {
    rotation 1 0 0 1.5707963
    children [
      Cylinder {
        height 0.06
        radius 0.09
      }
    ]
  }
  physics Physics {
    density -1
    mass 1.5
  }
  controller "robot_controller"
}
DEF ROBOT_RED Robot {
  translation 0.75 0.026 0
  rotation 0 1 0 3.14159265
  children [
    Pose {
      rotation 1 0 0 1.5707963
      children [
        Shape {
          appearance PBRAppearance {
            baseColor 0.85 0.05 0.05
            roughness 0.62
            metalness 0.12
          }
          geometry Cylinder {
            height 0.048
            radius 0.07
          }
        }
      ]
    }
    Pose {
      rotation 1 0 0 1.5707963
      translation 0 -0.020 0
      children [
        Shape {
          appearance PBRAppearance {
            baseColor 0.07 0.07 0.08
            roughness 0.82
            metalness 0
          }
          geometry Cylinder {
            height 0.008
            radius 0.072
          }
        }
      ]
    }
    Pose {
      rotation 1 0 0 1.5707963
      translation 0 -0.001 0
      children [
        Shape {
          appearance PBRAppearance {
            baseColor 0.92 0.48 0
            roughness 0.5
            metalness 0
            emissiveColor 0.4 0.12 0
          }
          geometry Cylinder {
            height 0.004
            radius 0.071
          }
        }
      ]
    }
    Pose {
      translation 0 0.030 0
      children [
        Shape {
          appearance PBRAppearance {
            roughness 0.2
            metalness 0
            emissiveColor 0.72 0.72 0.72
          }
          geometry IndexedFaceSet {
            coord Coordinate {
              point [
                0.044 0 0
                -0.015 0 0.03
                -0.015 0 -0.03
              ]
            }
            coordIndex [
              0, 1, 2, -1, 2, 1, 0, -1
            ]
          }
        }
      ]
    }
    Pose {
      translation 0.024 0.031 0.018
      children [
        Shape {
          appearance PBRAppearance {
            baseColor 1 0.62 0
            roughness 0.2
            metalness 0
            emissiveColor 0.65 0.32 0
          }
          geometry Cylinder {
            height 0.005
            radius 0.006
          }
        }
      ]
    }
    Pose {
      translation 0.024 0.031 -0.018
      children [
        Shape {
          appearance PBRAppearance {
            baseColor 1 0.62 0
            roughness 0.2
            metalness 0
            emissiveColor 0.65 0.32 0
          }
          geometry Cylinder {
            height 0.005
            radius 0.006
          }
        }
      ]
    }
    # RED wheel1: eixo radial para fora; centro = 0.07 + 0.009 = 0.079
    HingeJoint {
      jointParameters HingeJointParameters {
        axis 1.0000 0 0.0000
        anchor 0.07900 0 0.00000
      }
      device [
        RotationalMotor {
          name "wheel1 motor"
          maxVelocity 14
        }
      ]
      endPoint Solid {
        translation 0.07900 0 0.00000
        rotation 0 0 1 0
        children [
          Pose {
            rotation 0.0000 0 -1.0000 1.5707963
            children [
              Shape {
                appearance PBRAppearance {
                  baseColor 0.08 0.08 0.10
                  roughness 0.93
                  metalness 0
                }
                geometry Cylinder {
                  height 0.018
                  radius 0.026
                }
              }
            ]
          }
          Pose {
            rotation 0.0000 0 -1.0000 1.5707963
            children [
              Shape {
                appearance PBRAppearance {
                  baseColor 0.72 0.72 0.74
                  roughness 0.42
                  metalness 0.32
                }
                geometry Cylinder {
                  height 0.02
                  radius 0.012
                }
              }
            ]
          }
        ]
        name "viper_wheel1"
        contactMaterial "robot"
        boundingObject Sphere {
          radius 0.026
        }
        physics Physics {
          density -1
          mass 0.07
        }
      }
    }
    # RED wheel2: eixo radial para fora; centro = 0.079 em 120 graus
    HingeJoint {
      jointParameters HingeJointParameters {
        axis 1.0000 0 0.0000
        anchor -0.03950 0 0.06842
      }
      device [
        RotationalMotor {
          name "wheel2 motor"
          maxVelocity 14
        }
      ]
      endPoint Solid {
        translation -0.03950 0 0.06842
        rotation 0 0 1 0
        children [
          Pose {
            rotation 0.0000 0 -1.0000 1.5707963
            children [
              Shape {
                appearance PBRAppearance {
                  baseColor 0.08 0.08 0.10
                  roughness 0.93
                  metalness 0
                }
                geometry Cylinder {
                  height 0.018
                  radius 0.026
                }
              }
            ]
          }
          Pose {
            rotation 0.0000 0 -1.0000 1.5707963
            children [
              Shape {
                appearance PBRAppearance {
                  baseColor 0.72 0.72 0.74
                  roughness 0.42
                  metalness 0.32
                }
                geometry Cylinder {
                  height 0.02
                  radius 0.012
                }
              }
            ]
          }
        ]
        name "viper_wheel2"
        contactMaterial "robot"
        boundingObject Sphere {
          radius 0.026
        }
        physics Physics {
          density -1
          mass 0.07
        }
      }
    }
    # RED wheel3: eixo radial para fora; centro = 0.079 em 240 graus
    HingeJoint {
      jointParameters HingeJointParameters {
        axis 1.0000 0 0.0000
        anchor -0.03950 0 -0.06842
      }
      device [
        RotationalMotor {
          name "wheel3 motor"
          maxVelocity 14
        }
      ]
      endPoint Solid {
        translation -0.03950 0 -0.06842
        rotation 0 0 1 0
        children [
          Pose {
            rotation 0.0000 0 -1.0000 1.5707963
            children [
              Shape {
                appearance PBRAppearance {
                  baseColor 0.08 0.08 0.10
                  roughness 0.93
                  metalness 0
                }
                geometry Cylinder {
                  height 0.018
                  radius 0.026
                }
              }
            ]
          }
          Pose {
            rotation 0.0000 0 -1.0000 1.5707963
            children [
              Shape {
                appearance PBRAppearance {
                  baseColor 0.72 0.72 0.74
                  roughness 0.42
                  metalness 0.32
                }
                geometry Cylinder {
                  height 0.02
                  radius 0.012
                }
              }
            ]
          }
        ]
        name "viper_wheel3"
        contactMaterial "robot"
        boundingObject Sphere {
          radius 0.026
        }
        physics Physics {
          density -1
          mass 0.07
        }
      }
    }
    Receiver {
      channel -1
    }
  ]
  name "robot_red"
  contactMaterial "robot"
  boundingObject Pose {
    rotation 1 0 0 1.5707963
    children [
      Cylinder {
        height 0.048
        radius 0.07
      }
    ]
  }
  physics Physics {
    density -1
    mass 0.7
  }
  controller "robot_controller"
}
DEF SUPERVISOR Robot {
  translation 0 0.5 0
  children [
    Emitter {
      name "emitter_blue"
      channel -1
    }
    Emitter {
      name "emitter_red"
      channel -1
    }
  ]
  name "supervisor"
  controller "supervisor_controller"
  supervisor TRUE
}